Workbook
Name _Toc187670050: Formation!$A$4
Name _Toc187670051: Formation!$A$5
Name _Toc187670052: Formation!$A$22
Name _Toc187670053: Formation!$A$23
Name _Toc187670054: Formation!$A$24
Name _Toc187670055: Formation!$A$29
Name _Toc187670056: Formation!$A$30
Name _Toc187670057: Formation!$A$31
Name _Toc187670058: Formation!$A$32
Name _Toc187670059: Formation!$A$38
Name _Toc187670060: Formation!$A$39
Name _Toc187670061: Formation!$A$40
Name _Toc187670062: Formation!$A$41
Name _Toc187670063: Formation!$A$46
Name _Toc187670064: Formation!$A$47
Name _Toc187670065: Formation!$A$48
Name _Toc187670066: Formation!$A$49
Name _Toc187670067: Formation!$A$57
Name _Toc187670068: Formation!$A$58
Name _Toc187670069: Formation!$A$59
Name _Toc187670070: Formation!#REF!

Sheet Intégration
A1: Suivi de votre progression pour l'intégration de Team2Book
A2: Client : _________________________________________________
B3: Statut | C3: À compléter pour
A4: 1. Abonnement à Teamup Calendar | B4: FALSE | C4: =B33-120 -> 45658
A5: 2. Abonnement à Team2Book | B5: FALSE | C5: =B33-120 -> 45658
A6: 3. Communiquez-nous les coordonnées du coordonnateur des horaires | B6: FALSE | C6: =B33-105 -> 45673
A7: 4. Clé d'accès administrateur | B7: FALSE | C7: =B33-105 -> 45673
A8: 5. Bloc de configuration #1 : Configuration initiale | B8: FALSE | C8: =B33-100 -> 45678
A9: 6. Module de formation pour gestionnaire d'équipe #1 | B9: FALSE | C9: =B33-89 -> 45689
A10: 6.1 Bloc d'exercices pour gestionnaires d'équipe #1 | B10: FALSE | C10: =B33-96 -> 45682
A11: 6.2 Rencontre de formation #1 | B11: FALSE | C11: =B33-89 -> 45689
A12: 7. Module de formation pour gestionnaire d'équipe #2 | B12: FALSE | C12: =B33-68 -> 45710
A13: 7.1 Bloc d'exercices pour gestionnaires d'équipe #2 | B13: FALSE | C13: =B33-82 -> 45696
A14: 7.2 Bloc de configurations #2 à 12 | B14: FALSE | C14: =B33-75 -> 45703
A15: 7.3 Rencontre de formation #2 | B15: FALSE | C15: =B33-68 -> 45710
A16: 8. Module de formation pour gestionnaire d'équipe #3 | B16: FALSE | C16: =B33-43 -> 45735
A17: 8.1 Bloc d'exercices pour gestionnaires d'équipe #3 | B17: FALSE | C17: =B33-57 -> 45721
A18: 8.2 Bloc de configurations #13 à 17 | B18: FALSE | C18: =B33-50 -> 45728
A19: 8.3 Renconre de formation #3 (optionnelle) | B19: FALSE | C19: =B33-43 -> 45735
A20: 9. Module de formation pour gestionnaires d'équipe #4 | B20: FALSE | C20: =B33-22 -> 45756
A21: 9.1 Bloc d'exercices pour gestionnaires d'équipe #4 | B21: FALSE | C21: =B33-36 -> 45742
A22: 9.2 Bloc de configuration #18 : Paramètres | B22: FALSE | C22: =B33-29 -> 45749
A23: 9.3 Rencontre de formation #4 (optionnelle) | B23: FALSE | C23: =B33-22 -> 45756
A24: 10. Module de formation pour consommateurs #1 | B24: FALSE | C24: =B33-66 -> 45712
A25: 10.1 Bloc d'exercices pour consommateurs #1 | B25: FALSE | C25: =B33-66 -> 45712
A26: 11. Module de formation pour consommateurs #2 (optionnel) | B26: FALSE | C26: =B33-40 -> 45738
A27: 12. Module de formation pour spectateurs #1 | B27: FALSE | C27: =B33-16 -> 45762
A28: 12.1 Bloc d'exercices pour spectateurs #1 | B28: FALSE | C28: =B33-16 -> 45762
A29: 13. comparaison avec votre horaire existant | B29: FALSE | C29: =B33-45 -> 45733
A30: 14. Demandez à vos consommateurs d'entrer leurs disponibilités dans Teamup | B30: FALSE | C30: =B33-61 -> 45717
A31: 15. Laissez tomber votre horaire précédent et utilisez maintenant Teamup | B31: FALSE | C31: =B33 -> 45778
A33: Date de déploiement désirée : | B33: 45778
A35: Note : Veuillez-vous référer au " Guide d'Intégration de Team2Book "

Sheet Configuration
A1: Suivi de votre progression de la configuration de Team2Book
A2: Client : _________________________________________________
B3: Statut | C3: À compléter pour
A4: Configuration #1 : Configuration initiale | B4: FALSE | C4: =(Intégration!B33)-100 -> 45678
A5: Configuration #2 : Détails du client | B5: FALSE | C5: =(Intégration!B33)-82 -> 45696
A6: Configuration #3 : Catégorie de ressources | B6: FALSE | C6: =(Intégration!B33)-82 -> 45696
A7: Configuration #4 : Rôles des consommateurs | B7: FALSE | C7: =(Intégration!B33)-81 -> 45697
A8: Configuration #5 : Ressources | B8: FALSE | C8: =(Intégration!B33)-81 -> 45697
A9: Configuration #6 : Priorité de vos consommateurs | B9: FALSE | C9: =(Intégration!B33)-80 -> 45698
A10: Configuration #7 : Préférences de ressources pour vos consommateurs | B10: FALSE | C10: =(Intégration!B33)-80 -> 45698
A11: Configuration #8 : Couleur du sous-calendrier de disponibilités de chaque consommateur | B11: FALSE | C11: =(Intégration!B33)-79 -> 45699
A12: Configuration #9 : Type de sous-calendrier de disponibilités | B12: FALSE | C12: =(Intégration!B33)-78 -> 45700
A13: Configuration #10 : Heures de disponibilités habituelles pour chaque consommateur. | B13: FALSE | C13: =(Intégration!B33)-77 -> 45701
A14: Configuration #11 : Préparation pour la création des consommateurs | B14: FALSE | C14: =(Intégration!B33)-76 -> 45702
A15: Configuration #12 : Consommateurs | B15: FALSE | C15: =(Intégration!B33)-75 -> 45703
A16: Configuration #13 : Spectateurs | B16: FALSE | C16: =(Intégration!B33)-56 -> 45722
A17: Configuration #14 : Gestionnaires d’équipe | B17: FALSE | C17: =(Intégration!B33)-57 -> 45721
A18: Configuration #15 : Événements spéciaux | B18: FALSE | C18: =(Intégration!B33)-54 -> 45724
A19: Configuration #16 : Contraintes | B19: FALSE | C19: =(Intégration!B33)-52 -> 45726
A20: Configuration #17 : Notifications | B20: FALSE | C20: =(Intégration!B33)-50 -> 45728
A21: Configuration #18 : Paramètres | B21: FALSE | C21: =(Intégration!B33)-29 -> 45749
A23: Note : Veuillez-vous référer au " Guide de configuration de Team2Book "

Sheet Formation
A1: Suivi de votre progression pour la formation de Team2Book
A2: Client : _________________________________________________
B3: Statut | C3: À compléter pour
A4: Module de formation pour gestionnaire d’équipe #1 | B4: FALSE | C4: =(Intégration!B33)-89 -> 45689
A5: Bloc d’exercices pour gestionnaires d’équipe #1 | B5: FALSE | C5: =(Intégration!B33)-96 -> 45682
A6: GE.1.1 Connexion au tableau de bord de Team2Book | B6: FALSE | C6: =(Intégration!B33)-96 -> 45682
A7: GE.1.2 Connecxion à Teamup à partir du Tableau de bord de Team2Book | B7: FALSE | C7: =(Intégration!B33)-96 -> 45682
A8: GE.1.3 Installation de l’application mobile Teamup Calendar | B8: FALSE | C8: =(Intégration!B33)-96 -> 45682
A9: GE.1.4 Ajoutez un nouveau rôle de consommateur. | B9: FALSE | C9: =(Intégration!B33)-96 -> 45682
A10: GE.1.5 Ajoutez une nouvelle catégorie de ressources | B10: FALSE | C10: =(Intégration!B33)-96 -> 45682
A11: GE.1.6 Ajoutez une nouvelle ressource | B11: FALSE | C11: =(Intégration!B33)-96 -> 45682
A12: GE.1.7 Ajoutez un consommateur | B12: FALSE | C12: =(Intégration!B33)-96 -> 45682
A13: GE.1.8 Ajoutez une disponibilité | B13: FALSE | C13: =(Intégration!B33)-96 -> 45682
A14: GE.1.9 Exécutez le planificateur | B14: FALSE | C14: =(Intégration!B33)-96 -> 45682
A15: GE.1.10 Vérifiez la ressource attribuée pour l’événement de consommateur | B15: FALSE | C15: =(Intégration!B33)-96 -> 45682
A16: GE.1.11 Modifiez la vue de calendrier de Teamup Calendar | B16: FALSE | C16: =(Intégration!B33)-96 -> 45682
A17: GE.1.12 Affichez les événements d’un seul sous-calendrier et masquer tous les autres | B17: FALSE | C17: =(Intégration!B33)-96 -> 45682
A18: GE.1.13 Affichez les événements des sous-calendriers d’un groupe | B18: FALSE | C18: =(Intégration!B33)-96 -> 45682
A19: GE.1.14 Affichez les événements de 2 sous-calendriers ou plus | B19: FALSE | C19: =(Intégration!B33)-96 -> 45682
A20: GE.1.15 Filtrez les événements | B20: FALSE | C20: =(Intégration!B33)-96 -> 45682
A21: GE.1.16 Rafraîchissez le contenu de votre calendrier Teamup | B21: FALSE | C21: =(Intégration!B33)-96 -> 45682
A22: Rencontre de formation #1 | B22: FALSE | C22: =(Intégration!B33)-89 -> 45689
A23: Module de formation pour gestionnaire d’équipe #2 | B23: FALSE | C23: =(Intégration!B33)-68 -> 45710
A24: Bloc d’exercices pour gestionnaires d’équipe #2 | B24: FALSE | C24: =(Intégration!B33)-82 -> 45696
A25: GE.2.1 Modifiez la couleur du sous-calendrier de ressource | B25: FALSE | C25: =(Intégration!B33)-82 -> 45696
A26: GE.2.2 Modifiez la priorité du consommateur | B26: FALSE | C26: =(Intégration!B33)-82 -> 45696
A27: GE.2.3 Modifiez les préférences de ressources pour un consommateur | B27: FALSE | C27: =(Intégration!B33)-82 -> 45696
A28: GE.2.4 Effacez un consommateur | B28: FALSE | C28: =(Intégration!B33)-82 -> 45696
A29: Bloc de configurations #2 à 12 | B29: FALSE | C29: =(Intégration!B33)-75 -> 45703
A30: Rencontre de formation #2 | B30: FALSE | C30: =(Intégration!B33)-68 -> 45710
A31: Module de formation pour gestionnaire d’équipe #3 | B31: FALSE | C31: =(Intégration!B33)-43 -> 45735
A32: Bloc d’exercices pour gestionnaires d’équipe #3 | B32: FALSE | C32: =(Intégration!B33)-57 -> 45721
A33: GE.3.1 Ajoutez un « Type d’événement spécial » pour le sans rendez-vous | B33: FALSE | C33: =(Intégration!B33)-57 -> 45721
A34: GE.3.2 Assignez un médecin au sans rendez-vous | B34: FALSE | C34: =(Intégration!B33)-57 -> 45721
A35: GE.3.3 Ajoutez une contrainte (optionnelle) | B35: FALSE | C35: =(Intégration!B33)-57 -> 45721
A36: GE.3.4 Effacez une contrainte (optionnelle) | B36: FALSE | C36: =(Intégration!B33)-57 -> 45721
A37: GE.3.5 Mettez à jour le contenu de la notification transmise chaque mois (optionnelle) | B37: FALSE | C37: =(Intégration!B33)-57 -> 45721
A38: Bloc de configurations #13 à #17 | B38: FALSE | C38: =(Intégration!B33)-50 -> 45728
A39: Rencontre de formation #3 (optionnelle) | B39: FALSE | C39: =(Intégration!B33)-43 -> 45735
A40: Module de formation pour gestionnaires d’équipe #4 | B40: FALSE | C40: =(Intégration!B33)-22 -> 45756
...
